<mujoco model="a1_description">
    <compiler angle="radian" meshdir="mesh/" />
    <size njmax="500" nconmax="100" />
    <option gravity='0 0 -9.81' iterations='50' solver='PGS' timestep='0.002'/>

    <default>
        <geom contype="1" conaffinity="1" friction="0.6 0.3 0.3" rgba="0.5 0.6 0.7 1" margin="0.001" group="0"/>
        <!-- <geom  condim='3' contype="1" conaffinity="15" solref='0.001 2' friction='0.9 0.2 0.2'/> -->
        <light castshadow="false" diffuse="1 1 1"/>
        <motor ctrlrange="-33.5 33.5" ctrllimited="true"/>
        <camera fovy="60"/>
        <joint damping="0.01" armature="0.01" frictionloss="0.2" />

        <default class='visualgeom'>
            <geom material='visualgeom' condim='1' contype='0' conaffinity='0'/>
        </default>
    
    </default>

    <asset>
        <mesh name="trunk" file="trunk.stl" />
        <mesh name="hip" file="hip.stl" />
        <mesh name="thigh_mirror" file="thigh_mirror.stl" />
        <mesh name="calf" file="calf.stl" />
        <mesh name="thigh" file="thigh.stl" />
        <material name='visualgeom'  rgba='0.5 0.9 0.2 1'/>
    </asset>

    <asset>
        <texture type="skybox" builtin="gradient" rgb1="0.3 0.5 0.7" rgb2="0 0 0" width="512" height="512"/>
        <texture name="texplane" type="2d" builtin="checker" rgb1=".2 .3 .4" rgb2=".1 0.15 0.2"
            width="512" height="512" mark="cross" markrgb=".8 .8 .8"/>
        <texture name="texplane2" type="2d" builtin="checker" rgb1="0.8 .3 .4" rgb2=".0 0.8 0.2"
            width="512" height="512" mark="cross" markrgb=".8 .8 .8"/>

        <material name="matplane" reflectance="0." texture="texplane" texrepeat="1 1" texuniform="true"/>
        <material name="matplane2" reflectance="0.1" texture="texplane2" texrepeat="1 1" texuniform="true"/>
        <!-- <texture type="skybox" builtin="gradient" rgb1="1.0 1.0 1.0" rgb2="1.0 1.0 1.0" width="512" height="512"/> -->
        <texture name="plane" type="2d" builtin="flat" rgb1="1 1 1" rgb2="1 1 1" width="512" height="512" mark="cross" markrgb="0 0 0"/>
        <material name="plane" reflectance="0.0" texture="plane" texrepeat="3 3" texuniform="true"/>
    </asset>

    <visual>
        <rgba com="0.502 1.0 0 0.5" contactforce="0.98 0.4 0.4 0.7" contactpoint="1.0 1.0 0.6 0.4"/>
        <scale com="0.2" forcewidth="0.035" contactwidth="0.10" contactheight="0.04"/>
    </visual>

    <worldbody>
        <light directional="true" diffuse=".4 .4 .4" specular="0.1 0.1 0.1" pos="0 0 5.0" dir="0 0 -1" castshadow="false"/>
        <light directional="true" diffuse=".6 .6 .6" specular="0.2 0.2 0.2" pos="0 0 4" dir="0 0 -1"/>
        <geom name="ground" type="plane" size="0 0 1" pos="0.001 0 0" quat="1 0 0 0" material="matplane" condim="1" conaffinity='15'/>

        <body name="trunk" pos="0 0 0.2">
            <camera name='track' pos='0 -3 1' zaxis='0 -1 0.5' mode='track'/>
            <inertial pos="0.0 0.0041 -0.0005" mass="6.0" fullinertia='0.0158533 0.0377999 0.0456542 -3.66e-05 -6.11e-05 -2.75e-05' />
            <joint type="free" />
            <!-- <joint type='slide' axis='1 0 0' limited='false'/>
            <joint type='slide' axis='0 1 0' limited='false'/>
            <joint type='slide' axis='0 0 1' limited='false' ref='1.00'/>
            <joint type='ball' limited='false'/> -->
            <geom type="mesh" contype="0" conaffinity="0" group="1" rgba="0.1 0.1 0.1 1" mesh="trunk" />
            <geom size="0.13 0.04675 0.057" type="box" rgba="0.913725 0.913725 0.847059 0" />
            <geom size="0.0005 0.0005 0.0005" pos="-0.01592 -0.06659 -0.00617" type="box" contype="0" conaffinity="0" group="1" rgba="0.8 0 0 0" />
            <geom size="0.0005 0.0005 0.0005" pos="-0.01592 -0.06659 -0.00617" type="box" rgba="0.8 0 0 0" />
            <site name="imu" pos="0 0 0"/>

            <body name="FR_hip" pos="0.1805 -0.047 0">
                <inertial pos="-0.003311 -0.000635 3.1e-05"  mass="0.696" fullinertia='0.000469246 0.00080749 0.000552929 9.409e-06 -3.42e-07 4.66e-07' />
                <joint name="FR_hip_joint" pos="0 0 0" axis="1 0 0" limited="true" range="-0.802851455917 0.802851455917" />
                <geom quat="0 1 0 0" type="mesh" contype="0" conaffinity="0" group="1" rgba="0.1 0.1 0.1 1" mesh="hip" />
                <geom size="0.046 0.02" pos="0 -0.045 0" quat="0.707107 0.707107 0 0" type="cylinder" rgba="0.913725 0.913725 0.847059 0" />
                <geom size="0.031 0.02" pos="0 -0.07 0" quat="0.707107 0.707107 0 0" type="cylinder" rgba="0.913725 0.913725 0.847059 0" />

                <body name="FR_thigh" pos="0 -0.0838 0">
                    <inertial pos="-0.003237 0.022327 -0.027326" mass="1.013" fullinertia='0.005529065 0.005139339 0.001367788 -4.825e-06 0.000343869 -2.2448e-05'/>
                    <joint name="FR_thigh_joint" pos="0 0 0" axis="0 1 0" limited="true" range="-1.0471975512 4.18879020479"/>
                    <geom type="mesh" contype="0" conaffinity="0" group="1" rgba="0.1 0.1 0.1 1" mesh="thigh_mirror" />
                    <geom size="0.1065 0.01225 0.017" pos="0 0 -0.1065" quat="0.707107 0 0.707107 0" type="box" rgba="0.913725 0.913725 0.847059 0" />
                    <body name="FR_calf" pos="0 0 -0.2">
                        <inertial pos="0.006435 0.0 -0.107388" mass="0.166" fullinertia='0.002997972 0.003014022 3.2426e-05 0.0 -0.000141163 0.0' />
                        <joint name="FR_calf_joint" pos="0 0 0" axis="0 1 0" limited="true" range="-2.69653369433 -0.916297857297" />
                        <geom type="mesh" contype="0" conaffinity="0" group="1" rgba="0.9 0.9 0.9 1" mesh="calf" />
                        <geom size="0.1065 0.008 0.008" pos="0 0 -0.1065" quat="0.707107 0 0.707107 0" type="box" rgba="0 0 0 0" />
                        <geom size="0.01" pos="0 0 -0.2" contype="0" conaffinity="0" group="1" rgba="0 0 0 0" />
                        <geom size="0.02" pos="0 0 -0.2" rgba="0 0 0 0" />
                    </body>
                </body>
            </body>
            <body name="FL_hip" pos="0.1805 0.047 0">
                <inertial pos="-0.003311 0.000635 3.1e-05" mass="0.696" fullinertia='0.000469246 0.00080749 0.000552929 -9.409e-06 -3.42e-07 -4.66e-07' />
                <joint name="FL_hip_joint" pos="0 0 0" axis="1 0 0" limited="true" range="-0.802851455917 0.802851455917" />
                <geom type="mesh" contype="0" conaffinity="0" group="1" rgba="0.1 0.1 0.1 1" mesh="hip" />
                <geom size="0.046 0.02" pos="0 0.045 0" quat="0.707107 0.707107 0 0" type="cylinder" rgba="0.913725 0.913725 0.847059 0" />
                <geom size="0.031 0.02" pos="0 0.07 0" quat="0.707107 0.707107 0 0" type="cylinder" rgba="0.913725 0.913725 0.847059 0" />

                <body name="FL_thigh" pos="0 0.0838 0">
                    <inertial pos="-0.003237 -0.022327 -0.027326" mass="1.013" fullinertia='0.005529065 0.005139339 0.001367788 4.825e-06 0.000343869 2.2448e-05' />
                    <joint name="FL_thigh_joint" pos="0 0 0" axis="0 1 0" limited="true" range="-1.0471975512 4.18879020479" />
                    <geom type="mesh" contype="0" conaffinity="0" group="1" rgba="0.1 0.1 0.1 1" mesh="thigh" />
                    <geom size="0.1065 0.01225 0.017" pos="0 0 -0.1065" quat="0.707107 0 0.707107 0" type="box" rgba="0.913725 0.913725 0.847059 0" />
                    <body name="FL_calf" pos="0 0 -0.2">
                        <inertial pos="0.006435 0.0 -0.107388"  mass="0.166" fullinertia='0.002997972 0.003014022 3.2426e-05 0.0 -0.000141163 0.0' />
                        <joint name="FL_calf_joint" pos="0 0 0" axis="0 1 0" limited="true" range="-2.69653369433 -0.916297857297" />
                        <geom type="mesh" contype="0" conaffinity="0" group="1" rgba="0.9 0.9 0.9 1" mesh="calf" />
                        <geom size="0.1065 0.008 0.008" pos="0 0 -0.1065" quat="0.707107 0 0.707107 0" type="box" rgba="0.913725 0.913725 0.847059 0" />
                        <geom size="0.01" pos="0 0 -0.2" contype="0" conaffinity="0" group="1" rgba="0 0 0 0" />
                        <geom size="0.02" pos="0 0 -0.2" rgba="0 0 0 0" />
                    </body>
                </body>
            </body>
            <body name="RR_hip" pos="-0.1805 -0.047 0">
                <inertial pos="0.003311 -0.000635 3.1e-05" mass="0.696" fullinertia='0.000469246 0.00080749 0.000552929 -9.409e-06 3.42e-07 4.66e-07' />
                <joint name="RR_hip_joint" pos="0 0 0" axis="1 0 0" limited="true" range="-0.802851455917 0.802851455917" />
                <geom quat="0 0 0 -1" type="mesh" contype="0" conaffinity="0" group="1" rgba="0.1 0.1 0.1 1" mesh="hip" />
                <geom size="0.046 0.02" quat="0.707107 0.707107 0 0" type="cylinder" rgba="0.913725 0.913725 0.847059 0" />
                <geom size="0.046 0.02" pos="0 -0.045 0" quat="0.707107 0.707107 0 0" type="cylinder" rgba="0.913725 0.913725 0.847059 0" />
                <geom size="0.031 0.02" pos="0 -0.07 0" quat="0.707107 0.707107 0 0" type="cylinder" rgba="0.913725 0.913725 0.847059 0" />
        
                <body name="RR_thigh" pos="0 -0.0838 0">
                    <inertial pos="-0.003237 0.022327 -0.027326" mass="1.013" fullinertia='0.005529065 0.005139339 0.001367788 -4.825e-06 0.000343869 -2.2448e-05' />
                    <joint name="RR_thigh_joint" pos="0 0 0" axis="0 1 0" limited="true" range="-1.0471975512 4.18879020479" />
                    <geom type="mesh" contype="0" conaffinity="0" group="1" rgba="0.1 0.1 0.1 1" mesh="thigh_mirror" />
                    <geom size="0.1065 0.01225 0.017" pos="0 0 -0.1065" quat="0.707107 0 0.707107 0" type="box" rgba="0.913725 0.913725 0.847059 0" />
                    <body name="RR_calf" pos="0 0 -0.2">
                        <inertial pos="0.006435 0.0 -0.107388" mass="0.166" fullinertia='0.002997972 0.003014022 3.2426e-05 0.0 -0.000141163 0.0' />
                        <joint name="RR_calf_joint" pos="0 0 0" axis="0 1 0" limited="true" range="-2.69653369433 -0.916297857297" />
                        <geom type="mesh" contype="0" conaffinity="0" group="1" rgba="0.9 0.9 0.9 1" mesh="calf" />
                        <geom size="0.1065 0.008 0.008" pos="0 0 -0.1065" quat="0.707107 0 0.707107 0" type="box" rgba="0 0 0 0" />
                        <geom size="0.01" pos="0 0 -0.2" contype="0" conaffinity="0" group="1" rgba="0 0 0 0" />
                        <geom size="0.02" pos="0 0 -0.2" rgba="0 0 0 0" />
                    </body>
                </body>
            </body>
            <body name="RL_hip" pos="-0.1805 0.047 0">
                <inertial pos="0.003311 0.000635 3.1e-05" mass="0.696" fullinertia='0.000469246 0.00080749 0.000552929 9.409e-06 3.42e-07 -4.66e-07' />
                <joint name="RL_hip_joint" pos="0 0 0" axis="1 0 0" limited="true" range="-0.802851455917 0.802851455917"  />
                <geom quat="0 0 1 0" type="mesh" contype="0" conaffinity="0" group="1" rgba="0.1 0.1 0.1 1" mesh="hip" />
                <geom size="0.046 0.02" quat="0.707107 0.707107 0 0" type="cylinder" rgba="0.913725 0.913725 0.847059 0" />
                <geom size="0.046 0.02" pos="0 0.045 0" quat="0.707107 0.707107 0 0" type="cylinder" rgba="0.913725 0.913725 0.847059 0" />
                <geom size="0.031 0.02" pos="0 0.07 0" quat="0.707107 0.707107 0 0" type="cylinder" rgba="0.913725 0.913725 0.847059 0" />

                <body name="RL_thigh" pos="0 0.0838 0">
                    <inertial pos="-0.003237 -0.022327 -0.027326" mass="1.013" fullinertia='0.005529065 0.005139339 0.001367788 4.825e-06 0.000343869 2.2448e-05' />
                    <joint name="RL_thigh_joint" pos="0 0 0" axis="0 1 0" limited="true" range="-1.0471975512 4.18879020479" />
                    <geom type="mesh" contype="0" conaffinity="0" group="1" rgba="0.1 0.1 0.1 1" mesh="thigh" />
                    <geom size="0.1065 0.01225 0.017" pos="0 0 -0.1065" quat="0.707107 0 0.707107 0" type="box" rgba="0.913725 0.913725 0.847059 0" />
                    <body name="RL_calf" pos="0 0 -0.2">
                        <inertial pos="0.006435 0.0 -0.107388" mass="0.166" fullinertia='0.002997972 0.003014022 3.2426e-05 0.0 -0.000141163 0.0' />
                        <joint name="RL_calf_joint" pos="0 0 0" axis="0 1 0" limited="true" range="-2.69653369433 -0.916297857297" />
                        <geom type="mesh" contype="0" conaffinity="0" group="1" rgba="0.9 0.9 0.9 1" mesh="calf" />
                        <geom size="0.1065 0.008 0.008" pos="0 0 -0.1065" quat="0.707107 0 0.707107 0" type="box" rgba="0 0 0 0" />
                        <geom size="0.01" pos="0 0 -0.2" contype="0" conaffinity="0" group="1" rgba="0 0 0 0" />
                        <geom size="0.02" pos="0 0 -0.2" rgba="0 0 0 0" />
                    </body>
                </body>
            </body>
        </body>
    </worldbody>
    <actuator>       
        
        <motor name="FR_hip"       gear="1" joint="FR_hip_joint"/>
        <motor name="FR_thigh"     gear="1" joint="FR_thigh_joint"/>
        <motor name="FR_calf"      gear="1" joint="FR_calf_joint"/>
        <motor name="FL_hip"       gear="1" joint="FL_hip_joint"/>
        <motor name="FL_thigh"     gear="1" joint="FL_thigh_joint"/>
        <motor name="FL_calf"      gear="1" joint="FL_calf_joint"/>
        <motor name="RR_hip"       gear="1" joint="RR_hip_joint"/>
        <motor name="RR_thigh"     gear="1" joint="RR_thigh_joint"/>
        <motor name="RR_calf"      gear="1" joint="RR_calf_joint" />
        <motor name="RL_hip"       gear="1" joint="RL_hip_joint"/>
        <motor name="RL_thigh"     gear="1" joint="RL_thigh_joint"/>
        <motor name="RL_calf"      gear="1" joint="RL_calf_joint"/>
    </actuator>

    <sensor>

        <jointpos name="FR_hip_pos"     joint="FR_hip_joint"/>
        <jointpos name="FR_thigh_pos"   joint="FR_thigh_joint"/>
        <jointpos name="FR_calf_pos"    joint="FR_calf_joint"/>
        <jointpos name="FL_hip_pos"     joint="FL_hip_joint"/>
        <jointpos name="FL_thigh_pos"   joint="FL_thigh_joint"/>
        <jointpos name="FL_calf_pos"    joint="FL_calf_joint"/>
        <jointpos name="RR_hip_pos"     joint="RR_hip_joint"/>
        <jointpos name="RR_thigh_pos"   joint="RR_thigh_joint"/>
        <jointpos name="RR_calf_pos"    joint="RR_calf_joint" />
        <jointpos name="RL_hip_pos"     joint="RL_hip_joint"/>
        <jointpos name="RL_thigh_pos"   joint="RL_thigh_joint"/>
        <jointpos name="RL_calf_pos"    joint="RL_calf_joint"/>

        <jointvel name="FR_hip_vel"     joint="FR_hip_joint"/>
        <jointvel name="FR_thigh_vel"   joint="FR_thigh_joint"/>
        <jointvel name="FR_calf_vel"    joint="FR_calf_joint"/>
        <jointvel name="FL_hip_vel"     joint="FL_hip_joint"/>
        <jointvel name="FL_thigh_vel"   joint="FL_thigh_joint"/>
        <jointvel name="FL_calf_vel"    joint="FL_calf_joint"/>
        <jointvel name="RR_hip_vel"     joint="RR_hip_joint"/>
        <jointvel name="RR_thigh_vel"   joint="RR_thigh_joint"/>
        <jointvel name="RR_calf_vel"    joint="RR_calf_joint" />
        <jointvel name="RL_hip_vel"     joint="RL_hip_joint"/>
        <jointvel name="RL_thigh_vel"   joint="RL_thigh_joint"/>
        <jointvel name="RL_calf_vel"    joint="RL_calf_joint"/>

        <accelerometer name="Body_Acc" site="imu"/>

        <gyro name="Body_Gyro" site="imu"/>

        <framepos name="Body_Pos" objtype=site objname="imu"/>

        <framequat name="Body_Quat" objtype=site objname="imu"/>
        
    
    </sensor>
</mujoco>